Конечно! Вот пример использования блока Try{} Catch{} в PowerShell для обработки исключений:

```powershell
function Divide-Numbers {
    param(
        [int]$numerator,
        [int]$denominator
    )

    try {
        $result = $numerator / $denominator
        Write-Host "Результат деления: $result"
    }
    catch {
        Write-Host "Произошла ошибка при делении: $_.Exception.Message"
    }
}

# Вызов функции с передачей аргументов
Divide-Numbers -numerator 10 -denominator 2
Divide-Numbers -numerator 10 -denominator 0
```

В этом примере мы создали функцию "Divide-Numbers", которая делит два числа. Мы используем блок Try{} Catch{} для обработки исключений, которые могут возникнуть при делении на ноль. Если исключение возникает в блоке Try{}, то управление передается в блок Catch{}, где мы выводим сообщение об ошибке.

